Workbook

Sheet input Licensee sales
AF1: 1447.6657
E2: =SUM(E5:E4931) -> 216 | F2: =SUM(F5:F4930) -> 5727625.4 | G2: =SUM(G5:G4931) -> 47 | H2: =SUM(H5:H4930) -> 1334519 | I2: =SUM(I5:I4931) -> 2594 | J2: =SUM(J5:J4930) -> 60596753 | K2: =SUM(K5:K4931) -> 2223 | L2: =SUM(L5:L4930) -> 52723434 | M2: =SUM(M5:M4931) -> 2896 | N2: =SUM(N5:N4930) -> 68110687 | O2: =SUM(O5:O4931) -> 6264 | P2: =SUM(P5:P4930) -> 1.7034867e+08 | Q2: =SUM(Q5:Q4931) -> 2702 | R2: =SUM(R5:R4930) -> 76267168 | S2: =SUM(S5:S4931) -> 0 | T2: =SUM(T5:T4930) -> 0 | U2: =SUM(U5:U4931) -> 0 | V2: =SUM(V5:V4930) -> 0 | W2: =SUM(W5:W4931) -> 0 | X2: =SUM(X5:X4930) -> 0 | Y2: =SUM(Y5:Y4931) -> 0 | Z2: =SUM(Z5:Z4930) -> 0 | AA2: =SUM(AA5:AA4930) -> 0 | AB2: =SUM(AB5:AB4930) -> 0 | AC2: =SUM(AC5:AC4931) -> 16942 | AD2: =SUM(AD5:AD4930) -> 4.3510885e+08 | AF2: 1408.9662
E3: units | F3: amounts | G3: units | H3: amounts | I3: units | J3: amounts | K3: units | L3: amounts | M3: units | N3: amounts | O3: units | P3: amounts | Q3: units | R3: amounts | S3: units | T3: amounts | U3: units | V3: amounts | W3: units | X3: amounts | Y3: units | Z3: amounts | AA3: units | AB3: amounts | AF3: 1382.7578
A4: Customer | B4: City / Province | C4: Store Type | D4: Product group | E4: 46023 | G4: 46054 | I4: 46082 | K4: 46113 | M4: 46143 | O4: 46174 | Q4: 46204 | S4: 46235 | U4: 46266 | W4: 46296 | Y4: 46327 | AA4: 46357 | AC4: YTD_Units | AD4: YTD_Sales | AF4: =(AF1+AF2+AF3)/3 -> 1413.1299 | AH4: =(AH1+AH2+AH3)/3 -> 0 | AJ4: =(AJ1+AJ2+AJ3)/3 -> 0 | AL4: =(AL1+AL2+AL3)/3 -> 0
A5: LEURU S.A | B5: Cap Fed | C5: Levi's Store | D5: Bodywear | I5: 2594 | J5: 60596753 | K5: 1951 | L5: 44919824 | M5: 2581 | N5: 59424944 | O5: 5675 | P5: 1.5396716e+08 | Q5: 2650 | R5: 74808826 | AC5: =AA5+Y5+W5+U5+S5+Q5+O5+M5+K5+I5+G5+E5 -> 15451 | AD5: =AB5+Z5+X5+V5+T5+R5+P5+N5+L5+J5+H5+F5 -> 3.9371751e+08 | AE5: =E5+G5+I5 -> 2594 | AF5: =(F5+H5+J5)/$AF$4 -> 42881.233 | AG5: =K5+M5+O5 -> 10207 | AH5: =(L5+N5+P5)/$AH$4 -> #DIV/0! | AI5: =U5+S5+Q5 -> 2650 | AJ5: =(V5+T5+R5)/$AJ$4 -> #DIV/0! | AK5: =W5+Y5+AA5 -> 0 | AL5: =(X5+Z5+AB5)/$AL$4 -> #DIV/0!
A6: ML FULL | B6: Cap Fed | C6: Multibrand | D6: Bodywear | K6: 10 | L6: 249366.4 | O6: 20 | P6: 498732.8 | AC6: =AA6+Y6+W6+U6+S6+Q6+O6+M6+K6+I6+G6+E6 -> 30 | AD6: =AB6+Z6+X6+V6+T6+R6+P6+N6+L6+J6+H6+F6 -> 748099.2 | AE6: =E6+G6+I6 -> 0 | AF6: =(F6+H6+J6)/$AF$4 -> 0 | AG6: =K6+M6+O6 -> 30 | AH6: =(L6+N6+P6)/$AH$4 -> #DIV/0! | AI6: =U6+S6+Q6 -> 0 | AJ6: =(V6+T6+R6)/$AJ$4 -> #DIV/0! | AK6: =W6+Y6+AA6 -> 0 | AL6: =(X6+Z6+AB6)/$AL$4 -> #DIV/0!
A7: GONZALES MARIA ESTER | B7: Cap Fed | C7: Levi's Store (franchise) | D7: Bodywear | M7: 32 | N7: 847845.76 | O7: 60 | P7: 1589710.8 | Q7: 53 | R7: 1472369.1 | AC7: =AA7+Y7+W7+U7+S7+Q7+O7+M7+K7+I7+G7+E7 -> 145 | AD7: =AB7+Z7+X7+V7+T7+R7+P7+N7+L7+J7+H7+F7 -> 3909925.7 | AE7: =E7+G7+I7 -> 0 | AF7: =(F7+H7+J7)/$AF$4 -> 0 | AG7: =K7+M7+O7 -> 92 | AH7: =(L7+N7+P7)/$AH$4 -> #DIV/0! | AI7: =U7+S7+Q7 -> 53 | AJ7: =(V7+T7+R7)/$AJ$4 -> #DIV/0! | AK7: =W7+Y7+AA7 -> 0 | AL7: =(X7+Z7+AB7)/$AL$4 -> #DIV/0!
A8: MONTEMURRO&HERNANDEZ S H | B8: Cap Fed | C8: Levi's Store (franchise) | D8: Bodywear | O8: 36 | P8: 953826.48 | AC8: =AA8+Y8+W8+U8+S8+Q8+O8+M8+K8+I8+G8+E8 -> 36 | AD8: =AB8+Z8+X8+V8+T8+R8+P8+N8+L8+J8+H8+F8 -> 953826.48 | AE8: =E8+G8+I8 -> 0 | AF8: =(F8+H8+J8)/$AF$4 -> 0 | AG8: =K8+M8+O8 -> 36 | AH8: =(L8+N8+P8)/$AH$4 -> #DIV/0! | AI8: =U8+S8+Q8 -> 0 | AJ8: =(V8+T8+R8)/$AJ$4 -> #DIV/0! | AK8: =W8+Y8+AA8 -> 0 | AL8: =(X8+Z8+AB8)/$AL$4 -> #DIV/0!
A9: LIEBE S R L | B9: Cap Fed | C9: Levi's Store (franchise) | D9: Bodywear | E9: 76 | F9: 2013633.7 | K9: 49 | L9: 1298263.8 | AC9: =AA9+Y9+W9+U9+S9+Q9+O9+M9+K9+I9+G9+E9 -> 125 | AD9: =AB9+Z9+X9+V9+T9+R9+P9+N9+L9+J9+H9+F9 -> 3311897.5 | AE9: =E9+G9+I9 -> 76 | AF9: =(F9+H9+J9)/$AF$4 -> 1424.9459 | AG9: =K9+M9+O9 -> 49 | AH9: =(L9+N9+P9)/$AH$4 -> #DIV/0! | AI9: =U9+S9+Q9 -> 0 | AJ9: =(V9+T9+R9)/$AJ$4 -> #DIV/0! | AK9: =W9+Y9+AA9 -> 0 | AL9: =(X9+Z9+AB9)/$AL$4 -> #DIV/0!
A10: JAF S R L | B10: Cap Fed | C10: Levi's Store (franchise) | D10: Bodywear | O10: 26 | P10: 688874.68 | AC10: =AA10+Y10+W10+U10+S10+Q10+O10+M10+K10+I10+G10+E10 -> 26 | AD10: =AB10+Z10+X10+V10+T10+R10+P10+N10+L10+J10+H10+F10 -> 688874.68 | AE10: =E10+G10+I10 -> 0 | AF10: =(F10+H10+J10)/$AF$4 -> 0 | AG10: =K10+M10+O10 -> 26 | AH10: =(L10+N10+P10)/$AH$4 -> #DIV/0! | AI10: =U10+S10+Q10 -> 0 | AJ10: =(V10+T10+R10)/$AJ$4 -> #DIV/0! | AK10: =W10+Y10+AA10 -> 0 | AL10: =(X10+Z10+AB10)/$AL$4 -> #DIV/0!
A11: FRANQUICIE BAHIA BLANCA | B11: Cap Fed | C11: Levi's Store (franchise) | D11: Bodywear | E11: 66 | F11: 1753348.4 | O11: 44 | P11: 1165787.9 | AC11: =AA11+Y11+W11+U11+S11+Q11+O11+M11+K11+I11+G11+E11 -> 110 | AD11: =AB11+Z11+X11+V11+T11+R11+P11+N11+L11+J11+H11+F11 -> 2919136.3 | AE11: =E11+G11+I11 -> 66 | AF11: =(F11+H11+J11)/$AF$4 -> 1240.7553 | AG11: =K11+M11+O11 -> 44 | AH11: =(L11+N11+P11)/$AH$4 -> #DIV/0! | AI11: =U11+S11+Q11 -> 0 | AJ11: =(V11+T11+R11)/$AJ$4 -> #DIV/0! | AK11: =W11+Y11+AA11 -> 0 | AL11: =(X11+Z11+AB11)/$AL$4 -> #DIV/0!
A12: GONZALEZ MARIA ESTER | B12: Cap Fed | C12: Levi's Store (franchise) | D12: Bodywear | E12: 44 | F12: 1165787.9 | AC12: =AA12+Y12+W12+U12+S12+Q12+O12+M12+K12+I12+G12+E12 -> 44 | AD12: =AB12+Z12+X12+V12+T12+R12+P12+N12+L12+J12+H12+F12 -> 1165787.9 | AE12: =E12+G12+I12 -> 44 | AF12: =(F12+H12+J12)/$AF$4 -> 824.96869 | AG12: =K12+M12+O12 -> 0 | AH12: =(L12+N12+P12)/$AH$4 -> #DIV/0! | AI12: =U12+S12+Q12 -> 0 | AJ12: =(V12+T12+R12)/$AJ$4 -> #DIV/0! | AK12: =W12+Y12+AA12 -> 0 | AL12: =(X12+Z12+AB12)/$AL$4 -> #DIV/0!
A13: LEVIMAR SRL | B13: Cap Fed | C13: Levi's Store (franchise) | D13: Bodywear | E13: 30 | F13: 794855.4 | G13: 30 | H13: 794855.4 | M13: 55 | N13: 1457234.9 | AC13: =AA13+Y13+W13+U13+S13+Q13+O13+M13+K13+I13+G13+E13 -> 115 | AD13: =AB13+Z13+X13+V13+T13+R13+P13+N13+L13+J13+H13+F13 -> 3046945.7 | AE13: =E13+G13+I13 -> 60 | AF13: =(F13+H13+J13)/$AF$4 -> 1124.9573 | AG13: =K13+M13+O13 -> 55 | AH13: =(L13+N13+P13)/$AH$4 -> #DIV/0! | AI13: =U13+S13+Q13 -> 0 | AJ13: =(V13+T13+R13)/$AJ$4 -> #DIV/0! | AK13: =W13+Y13+AA13 -> 0 | AL13: =(X13+Z13+AB13)/$AL$4 -> #DIV/0!
A14: SANTIAGO CAMPIS | B14: Cap Fed | C14: Levi's Store (franchise) | D14: Bodywear | O14: 96 | P14: 2543537.3 | AC14: =AA14+Y14+W14+U14+S14+Q14+O14+M14+K14+I14+G14+E14 -> 96 | AD14: =AB14+Z14+X14+V14+T14+R14+P14+N14+L14+J14+H14+F14 -> 2543537.3 | AE14: =E14+G14+I14 -> 0 | AF14: =(F14+H14+J14)/$AF$4 -> 0 | AG14: =K14+M14+O14 -> 96 | AH14: =(L14+N14+P14)/$AH$4 -> #DIV/0! | AI14: =U14+S14+Q14 -> 0 | AJ14: =(V14+T14+R14)/$AJ$4 -> #DIV/0! | AK14: =W14+Y14+AA14 -> 0 | AL14: =(X14+Z14+AB14)/$AL$4 -> #DIV/0!
A15: WAIMEA PINAMAR | B15: Cap Fed | C15: Levi's Store (franchise) | D15: Bodywear | M15: 64 | N15: 1695691.5 | AC15: =AA15+Y15+W15+U15+S15+Q15+O15+M15+K15+I15+G15+E15 -> 64 | AD15: =AB15+Z15+X15+V15+T15+R15+P15+N15+L15+J15+H15+F15 -> 1695691.5 | AE15: =E15+G15+I15 -> 0 | AF15: =(F15+H15+J15)/$AF$4 -> 0 | AG15: =K15+M15+O15 -> 64 | AH15: =(L15+N15+P15)/$AH$4 -> #DIV/0! | AI15: =U15+S15+Q15 -> 0 | AJ15: =(V15+T15+R15)/$AJ$4 -> #DIV/0! | AK15: =W15+Y15+AA15 -> 0 | AL15: =(X15+Z15+AB15)/$AL$4 -> #DIV/0!
A16: MC PIE SRL | B16: Cap Fed | C16: Multibrand | D16: Bodywear | K16: 18 | L16: 476913.24 | M16: 27 | N16: 841611.6 | AC16: =AA16+Y16+W16+U16+S16+Q16+O16+M16+K16+I16+G16+E16 -> 45 | AD16: =AB16+Z16+X16+V16+T16+R16+P16+N16+L16+J16+H16+F16 -> 1318524.8 | AE16: =E16+G16+I16 -> 0 | AF16: =(F16+H16+J16)/$AF$4 -> 0 | AG16: =K16+M16+O16 -> 45 | AH16: =(L16+N16+P16)/$AH$4 -> #DIV/0! | AI16: =U16+S16+Q16 -> 0 | AJ16: =(V16+T16+R16)/$AJ$4 -> #DIV/0! | AK16: =W16+Y16+AA16 -> 0 | AL16: =(X16+Z16+AB16)/$AL$4 -> #DIV/0!
A17: AGALMA | B17: Sur | C17: Multibrand | D17: Bodywear | O17: 35 | P17: 1090978 | AC17: =AA17+Y17+W17+U17+S17+Q17+O17+M17+K17+I17+G17+E17 -> 35 | AD17: =AB17+Z17+X17+V17+T17+R17+P17+N17+L17+J17+H17+F17 -> 1090978 | AE17: =E17+G17+I17 -> 0 | AF17: =(F17+H17+J17)/$AF$4 -> 0 | AG17: =K17+M17+O17 -> 35 | AH17: =(L17+N17+P17)/$AH$4 -> #DIV/0! | AI17: =U17+S17+Q17 -> 0 | AJ17: =(V17+T17+R17)/$AJ$4 -> #DIV/0! | AK17: =W17+Y17+AA17 -> 0 | AL17: =(X17+Z17+AB17)/$AL$4 -> #DIV/0!
A18: RADA TILLY | B18: Sur | C18: Multibrand | D18: Bodywear | O18: 36 | P18: 1122148.8 | AC18: =AA18+Y18+W18+U18+S18+Q18+O18+M18+K18+I18+G18+E18 -> 36 | AD18: =AB18+Z18+X18+V18+T18+R18+P18+N18+L18+J18+H18+F18 -> 1122148.8 | AE18: =E18+G18+I18 -> 0 | AF18: =(F18+H18+J18)/$AF$4 -> 0 | AG18: =K18+M18+O18 -> 36 | AH18: =(L18+N18+P18)/$AH$4 -> #DIV/0! | AI18: =U18+S18+Q18 -> 0 | AJ18: =(V18+T18+R18)/$AJ$4 -> #DIV/0! | AK18: =W18+Y18+AA18 -> 0 | AL18: =(X18+Z18+AB18)/$AL$4 -> #DIV/0!
A19: MARATHON SRL | B19: Noa | C19: Multibrand | D19: Bodywear | O19: 144 | P19: 3860191.8 | AC19: =AA19+Y19+W19+U19+S19+Q19+O19+M19+K19+I19+G19+E19 -> 144 | AD19: =AB19+Z19+X19+V19+T19+R19+P19+N19+L19+J19+H19+F19 -> 3860191.8 | AE19: =E19+G19+I19 -> 0 | AF19: =(F19+H19+J19)/$AF$4 -> 0 | AG19: =K19+M19+O19 -> 144 | AH19: =(L19+N19+P19)/$AH$4 -> #DIV/0! | AI19: =U19+S19+Q19 -> 0 | AJ19: =(V19+T19+R19)/$AJ$4 -> #DIV/0! | AK19: =W19+Y19+AA19 -> 0 | AL19: =(X19+Z19+AB19)/$AL$4 -> #DIV/0!
A20: DELGADO JULIA MARCELA | B20: Córdoba | C20: Multibrand | D20: Bodywear | G20: 17 | H20: 539663.6 | AC20: =AA20+Y20+W20+U20+S20+Q20+O20+M20+K20+I20+G20+E20 -> 17 | AD20: =AB20+Z20+X20+V20+T20+R20+P20+N20+L20+J20+H20+F20 -> 539663.6 | AE20: =E20+G20+I20 -> 17 | AF20: =(F20+H20+J20)/$AF$4 -> 381.89242 | AG20: =K20+M20+O20 -> 0 | AH20: =(L20+N20+P20)/$AH$4 -> #DIV/0! | AI20: =U20+S20+Q20 -> 0 | AJ20: =(V20+T20+R20)/$AJ$4 -> #DIV/0! | AK20: =W20+Y20+AA20 -> 0 | AL20: =(X20+Z20+AB20)/$AL$4 -> #DIV/0!
A21: BELLETTINI JOSE GUSTAVO | B21: Córdoba | C21: Multibrand | D21: Bodywear | K21: 17 | L21: 529903.6 | AC21: =AA21+Y21+W21+U21+S21+Q21+O21+M21+K21+I21+G21+E21 -> 17 | AD21: =AB21+Z21+X21+V21+T21+R21+P21+N21+L21+J21+H21+F21 -> 529903.6 | AE21: =E21+G21+I21 -> 0 | AF21: =(F21+H21+J21)/$AF$4 -> 0 | AG21: =K21+M21+O21 -> 17 | AH21: =(L21+N21+P21)/$AH$4 -> #DIV/0! | AI21: =U21+S21+Q21 -> 0 | AJ21: =(V21+T21+R21)/$AJ$4 -> #DIV/0! | AK21: =W21+Y21+AA21 -> 0 | AL21: =(X21+Z21+AB21)/$AL$4 -> #DIV/0!
A22: ALONSO JUAN JOSE | B22: Córdoba | C22: Multibrand | D22: Bodywear | O22: 9 | P22: 280537.2 | Q22: -1 | R22: -14026.86 | AC22: =AA22+Y22+W22+U22+S22+Q22+O22+M22+K22+I22+G22+E22 -> 8 | AD22: =AB22+Z22+X22+V22+T22+R22+P22+N22+L22+J22+H22+F22 -> 266510.34 | AE22: =E22+G22+I22 -> 0 | AF22: =(F22+H22+J22)/$AF$4 -> 0 | AG22: =K22+M22+O22 -> 9 | AH22: =(L22+N22+P22)/$AH$4 -> #DIV/0! | AI22: =U22+S22+Q22 -> -1 | AJ22: =(V22+T22+R22)/$AJ$4 -> #DIV/0! | AK22: =W22+Y22+AA22 -> 0 | AL22: =(X22+Z22+AB22)/$AL$4 -> #DIV/0!
A23: DINOSAURIO | B23: Córdoba | C23: Multibrand | D23: Bodywear | M23: 137 | N23: 3843359.6 | AC23: =AA23+Y23+W23+U23+S23+Q23+O23+M23+K23+I23+G23+E23 -> 137 | AD23: =AB23+Z23+X23+V23+T23+R23+P23+N23+L23+J23+H23+F23 -> 3843359.6 | AE23: =E23+G23+I23 -> 0 | AF23: =(F23+H23+J23)/$AF$4 -> 0 | AG23: =K23+M23+O23 -> 137 | AH23: =(L23+N23+P23)/$AH$4 -> #DIV/0! | AI23: =U23+S23+Q23 -> 0 | AJ23: =(V23+T23+R23)/$AJ$4 -> #DIV/0! | AK23: =W23+Y23+AA23 -> 0 | AL23: =(X23+Z23+AB23)/$AL$4 -> #DIV/0!
A24: UGARTE Y CIA. S.R.L. | B24: Córdoba | C24: Multibrand | D24: Bodywear | K24: 96 | L24: 2693157.1 | AC24: =AA24+Y24+W24+U24+S24+Q24+O24+M24+K24+I24+G24+E24 -> 96 | AD24: =AB24+Z24+X24+V24+T24+R24+P24+N24+L24+J24+H24+F24 -> 2693157.1 | AE24: =E24+G24+I24 -> 0 | AF24: =(F24+H24+J24)/$AF$4 -> 0 | AG24: =K24+M24+O24 -> 96 | AH24: =(L24+N24+P24)/$AH$4 -> #DIV/0! | AI24: =U24+S24+Q24 -> 0 | AJ24: =(V24+T24+R24)/$AJ$4 -> #DIV/0! | AK24: =W24+Y24+AA24 -> 0 | AL24: =(X24+Z24+AB24)/$AL$4 -> #DIV/0!
A25: MULTIBRAND JEANS SRL | B25: GBA | C25: Multibrand | D25: Bodywear | K25: 82 | L25: 2556005.6 | AC25: =AA25+Y25+W25+U25+S25+Q25+O25+M25+K25+I25+G25+E25 -> 82 | AD25: =AB25+Z25+X25+V25+T25+R25+P25+N25+L25+J25+H25+F25 -> 2556005.6 | AE25: =E25+G25+I25 -> 0 | AF25: =(F25+H25+J25)/$AF$4 -> 0 | AG25: =K25+M25+O25 -> 82 | AH25: =(L25+N25+P25)/$AH$4 -> #DIV/0! | AI25: =U25+S25+Q25 -> 0 | AJ25: =(V25+T25+R25)/$AJ$4 -> #DIV/0! | AK25: =W25+Y25+AA25 -> 0 | AL25: =(X25+Z25+AB25)/$AL$4 -> #DIV/0!
A26: BRAVA MARKET ARGENTINA | B26: GBA | C26: Multibrand | D26: Bodywear | O26: 52 | P26: 1620881.6 | AC26: =AA26+Y26+W26+U26+S26+Q26+O26+M26+K26+I26+G26+E26 -> 52 | AD26: =AB26+Z26+X26+V26+T26+R26+P26+N26+L26+J26+H26+F26 -> 1620881.6 | AE26: =E26+G26+I26 -> 0 | AF26: =(F26+H26+J26)/$AF$4 -> 0 | AG26: =K26+M26+O26 -> 52 | AH26: =(L26+N26+P26)/$AH$4 -> #DIV/0! | AI26: =U26+S26+Q26 -> 0 | AJ26: =(V26+T26+R26)/$AJ$4 -> #DIV/0! | AK26: =W26+Y26+AA26 -> 0 | AL26: =(X26+Z26+AB26)/$AL$4 -> #DIV/0!
A27: PARENTI KARINA VERONICA | B27: GBA | C27: Multibrand | D27: Bodywear | O27: 31 | P27: 966294.8 | AC27: =AA27+Y27+W27+U27+S27+Q27+O27+M27+K27+I27+G27+E27 -> 31 | AD27: =AB27+Z27+X27+V27+T27+R27+P27+N27+L27+J27+H27+F27 -> 966294.8 | AE27: =E27+G27+I27 -> 0 | AF27: =(F27+H27+J27)/$AF$4 -> 0 | AG27: =K27+M27+O27 -> 31 | AH27: =(L27+N27+P27)/$AH$4 -> #DIV/0! | AI27: =U27+S27+Q27 -> 0 | AJ27: =(V27+T27+R27)/$AJ$4 -> #DIV/0! | AK27: =W27+Y27+AA27 -> 0 | AL27: =(X27+Z27+AB27)/$AL$4 -> #DIV/0!
AC28: =AA28+Y28+W28+U28+S28+Q28+O28+M28+K28+I28+G28+E28 -> 0 | AD28: =AB28+Z28+X28+V28+T28+R28+P28+N28+L28+J28+H28+F28 -> 0 | AE28: =E28+G28+I28 -> 0 | AF28: =(F28+H28+J28)/$AF$4 -> 0 | AG28: =K28+M28+O28 -> 0 | AH28: =(L28+N28+P28)/$AH$4 -> #DIV/0! | AI28: =U28+S28+Q28 -> 0 | AJ28: =(V28+T28+R28)/$AJ$4 -> #DIV/0! | AK28: =W28+Y28+AA28 -> 0 | AL28: =(X28+Z28+AB28)/$AL$4 -> #DIV/0!
AC29: =AA29+Y29+W29+U29+S29+Q29+O29+M29+K29+I29+G29+E29 -> 0 | AD29: =AB29+Z29+X29+V29+T29+R29+P29+N29+L29+J29+H29+F29 -> 0 | AE29: =E29+G29+I29 -> 0 | AF29: =(F29+H29+J29)/$AF$4 -> 0 | AG29: =K29+M29+O29 -> 0 | AH29: =(L29+N29+P29)/$AH$4 -> #DIV/0! | AI29: =U29+S29+Q29 -> 0 | AJ29: =(V29+T29+R29)/$AJ$4 -> #DIV/0! | AK29: =W29+Y29+AA29 -> 0 | AL29: =(X29+Z29+AB29)/$AL$4 -> #DIV/0!
AC30: =AA30+Y30+W30+U30+S30+Q30+O30+M30+K30+I30+G30+E30 -> 0 | AD30: =AB30+Z30+X30+V30+T30+R30+P30+N30+L30+J30+H30+F30 -> 0 | AE30: =E30+G30+I30 -> 0 | AF30: =(F30+H30+J30)/$AF$4 -> 0 | AG30: =K30+M30+O30 -> 0 | AH30: =(L30+N30+P30)/$AH$4 -> #DIV/0! | AI30: =U30+S30+Q30 -> 0 | AJ30: =(V30+T30+R30)/$AJ$4 -> #DIV/0! | AK30: =W30+Y30+AA30 -> 0 | AL30: =(X30+Z30+AB30)/$AL$4 -> #DIV/0!
AC31: =AA31+Y31+W31+U31+S31+Q31+O31+M31+K31+I31+G31+E31 -> 0 | AD31: =AB31+Z31+X31+V31+T31+R31+P31+N31+L31+J31+H31+F31 -> 0 | AE31: =E31+G31+I31 -> 0 | AF31: =(F31+H31+J31)/$AF$4 -> 0 | AG31: =K31+M31+O31 -> 0 | AH31: =(L31+N31+P31)/$AH$4 -> #DIV/0! | AI31: =U31+S31+Q31 -> 0 | AJ31: =(V31+T31+R31)/$AJ$4 -> #DIV/0! | AK31: =W31+Y31+AA31 -> 0 | AL31: =(X31+Z31+AB31)/$AL$4 -> #DIV/0!
AC32: =AA32+Y32+W32+U32+S32+Q32+O32+M32+K32+I32+G32+E32 -> 0 | AD32: =AB32+Z32+X32+V32+T32+R32+P32+N32+L32+J32+H32+F32 -> 0 | AE32: =E32+G32+I32 -> 0 | AF32: =(F32+H32+J32)/$AF$4 -> 0 | AG32: =K32+M32+O32 -> 0 | AH32: =(L32+N32+P32)/$AH$4 -> #DIV/0! | AI32: =U32+S32+Q32 -> 0 | AJ32: =(V32+T32+R32)/$AJ$4 -> #DIV/0! | AK32: =W32+Y32+AA32 -> 0 | AL32: =(X32+Z32+AB32)/$AL$4 -> #DIV/0!
AC33: =AA33+Y33+W33+U33+S33+Q33+O33+M33+K33+I33+G33+E33 -> 0 | AD33: =AB33+Z33+X33+V33+T33+R33+P33+N33+L33+J33+H33+F33 -> 0 | AE33: =E33+G33+I33 -> 0 | AF33: =(F33+H33+J33)/$AF$4 -> 0 | AG33: =K33+M33+O33 -> 0 | AH33: =(L33+N33+P33)/$AH$4 -> #DIV/0! | AI33: =U33+S33+Q33 -> 0 | AJ33: =(V33+T33+R33)/$AJ$4 -> #DIV/0! | AK33: =W33+Y33+AA33 -> 0 | AL33: =(X33+Z33+AB33)/$AL$4 -> #DIV/0!
AC34: =AA34+Y34+W34+U34+S34+Q34+O34+M34+K34+I34+G34+E34 -> 0 | AD34: =AB34+Z34+X34+V34+T34+R34+P34+N34+L34+J34+H34+F34 -> 0 | AE34: =E34+G34+I34 -> 0 | AF34: =(F34+H34+J34)/$AF$4 -> 0 | AG34: =K34+M34+O34 -> 0 | AH34: =(L34+N34+P34)/$AH$4 -> #DIV/0! | AI34: =U34+S34+Q34 -> 0 | AJ34: =(V34+T34+R34)/$AJ$4 -> #DIV/0! | AK34: =W34+Y34+AA34 -> 0 | AL34: =(X34+Z34+AB34)/$AL$4 -> #DIV/0!
AC35: =AA35+Y35+W35+U35+S35+Q35+O35+M35+K35+I35+G35+E35 -> 0 | AD35: =AB35+Z35+X35+V35+T35+R35+P35+N35+L35+J35+H35+F35 -> 0 | AE35: =E35+G35+I35 -> 0 | AF35: =(F35+H35+J35)/$AF$4 -> 0 | AG35: =K35+M35+O35 -> 0 | AH35: =(L35+N35+P35)/$AH$4 -> #DIV/0! | AI35: =U35+S35+Q35 -> 0 | AJ35: =(V35+T35+R35)/$AJ$4 -> #DIV/0! | AK35: =W35+Y35+AA35 -> 0 | AL35: =(X35+Z35+AB35)/$AL$4 -> #DIV/0!
AC36: =AA36+Y36+W36+U36+S36+Q36+O36+M36+K36+I36+G36+E36 -> 0 | AD36: =AB36+Z36+X36+V36+T36+R36+P36+N36+L36+J36+H36+F36 -> 0 | AE36: =E36+G36+I36 -> 0 | AF36: =(F36+H36+J36)/$AF$4 -> 0 | AG36: =K36+M36+O36 -> 0 | AH36: =(L36+N36+P36)/$AH$4 -> #DIV/0! | AI36: =U36+S36+Q36 -> 0 | AJ36: =(V36+T36+R36)/$AJ$4 -> #DIV/0! | AK36: =W36+Y36+AA36 -> 0 | AL36: =(X36+Z36+AB36)/$AL$4 -> #DIV/0!
AC37: =AA37+Y37+W37+U37+S37+Q37+O37+M37+K37+I37+G37+E37 -> 0 | AD37: =AB37+Z37+X37+V37+T37+R37+P37+N37+L37+J37+H37+F37 -> 0 | AE37: =E37+G37+I37 -> 0 | AF37: =(F37+H37+J37)/$AF$4 -> 0 | AG37: =K37+M37+O37 -> 0 | AH37: =(L37+N37+P37)/$AH$4 -> #DIV/0! | AI37: =U37+S37+Q37 -> 0 | AJ37: =(V37+T37+R37)/$AJ$4 -> #DIV/0! | AK37: =W37+Y37+AA37 -> 0 | AL37: =(X37+Z37+AB37)/$AL$4 -> #DIV/0!
AC38: =AA38+Y38+W38+U38+S38+Q38+O38+M38+K38+I38+G38+E38 -> 0 | AD38: =AB38+Z38+X38+V38+T38+R38+P38+N38+L38+J38+H38+F38 -> 0 | AE38: =E38+G38+I38 -> 0 | AF38: =(F38+H38+J38)/$AF$4 -> 0 | AG38: =K38+M38+O38 -> 0 | AH38: =(L38+N38+P38)/$AH$4 -> #DIV/0! | AI38: =U38+S38+Q38 -> 0 | AJ38: =(V38+T38+R38)/$AJ$4 -> #DIV/0! | AK38: =W38+Y38+AA38 -> 0 | AL38: =(X38+Z38+AB38)/$AL$4 -> #DIV/0!
AC39: =AA39+Y39+W39+U39+S39+Q39+O39+M39+K39+I39+G39+E39 -> 0 | AD39: =AB39+Z39+X39+V39+T39+R39+P39+N39+L39+J39+H39+F39 -> 0 | AE39: =E39+G39+I39 -> 0 | AF39: =(F39+H39+J39)/$AF$4 -> 0 | AG39: =K39+M39+O39 -> 0 | AH39: =(L39+N39+P39)/$AH$4 -> #DIV/0! | AI39: =U39+S39+Q39 -> 0 | AJ39: =(V39+T39+R39)/$AJ$4 -> #DIV/0! | AK39: =W39+Y39+AA39 -> 0 | AL39: =(X39+Z39+AB39)/$AL$4 -> #DIV/0!
... AC136: =AA136+Y136+W136+U136+S136+Q136+O136+M136+K136+I136+G136+E136 -> 0 | AD136: =AB136+Z136+X136+V136+T136+R136+P136+N136+L136+J136+H136+F136 -> 0 | AE136: =E136+G136+I136 -> 0 | AF136: =(F136+H136+J136)/$AF$4 -> 0 | AG136: =K136+M136+O136 -> 0 | AH136: =(L136+N136+P136)/$AH$4 -> #DIV/0! | AI136: =U136+S136+Q136 -> 0 | AJ136: =(V136+T136+R136)/$AJ$4 -> #DIV/0! | AK136: =W136+Y136+AA136 -> 0 | AL136: =(X136+Z136+AB136)/$AL$4 -> #DIV/0!
...

Sheet monthly
B2: Best Sox | D2: 01-2026 | E2: 02-2026 | F2: 03-2026 | G2: 1st quarter | H2: 04-2026 | I2: 05-2026 | J2: 06-2026 | K2: 2nd quarter | L2: 07-2026 | M2: 08-2026 | N2: 09-2026 | O2: 3th quarter | P2: 10-2026 | Q2: 11-2026 | R2: 12-2026 | S2: 4th quarter | T2: FY 2026
B4: dozens | D4: ='input Licensee sales'!E2 -> 216 | E4: ='input Licensee sales'!G2 -> 47 | F4: ='input Licensee sales'!I2 -> 2594 | G4: =SUM(D4:F4) -> 2857 | H4: ='input Licensee sales'!K2 -> 2223 | I4: ='input Licensee sales'!M2 -> 2896 | J4: ='input Licensee sales'!O2 -> 6264 | K4: =SUM(H4:J4) -> 11383 | L4: ='input Licensee sales'!Q2 -> 2702 | M4: ='input Licensee sales'!S2 -> 0 | N4: ='input Licensee sales'!U2 -> 0 | O4: =SUM(L4:N4) -> 2702 | P4: ='input Licensee sales'!W2 -> 0 | Q4: ='input Licensee sales'!Y2 -> 0 | R4: ='input Licensee sales'!AA2 -> 0 | S4: =SUM(P4:R4) -> 0 | T4: =G4+K4+O4+S4 -> 16942
B6: Sales | C6: ARS | D6: ='input Licensee sales'!F2 -> 5727625.4 | E6: ='input Licensee sales'!H2 -> 1334519 | F6: ='input Licensee sales'!J2 -> 60596753 | G6: =SUM(D6:F6) -> 67658897 | H6: ='input Licensee sales'!L2 -> 52723434 | I6: ='input Licensee sales'!N2 -> 68110687 | J6: ='input Licensee sales'!P2 -> 1.7034867e+08 | K6: =SUM(H6:J6) -> 2.9118279e+08 | L6: ='input Licensee sales'!R2 -> 76267168 | M6: ='input Licensee sales'!T2 -> 0 | N6: ='input Licensee sales'!V2 -> 0 | O6: =SUM(L6:N6) -> 76267168 | P6: ='input Licensee sales'!X2 -> 0 | Q6: ='input Licensee sales'!Z2 -> 0 | R6: ='input Licensee sales'!AB2 -> 0 | S6: =SUM(P6:R6) -> 0 | T6: =G6+K6+O6+S6 -> 4.3510885e+08
C7: 0.2
B8: Royalty | C8: =C6 -> ARS | D8: =$C7*D6 -> 1145525.1 | E8: =$C7*E6 -> 266903.8 | F8: =$C7*F6 -> 12119351 | G8: =SUM(D8:F8) -> 13531779 | H8: =$C7*H6 -> 10544687 | I8: =$C7*I6 -> 13622137 | J8: =$C7*J6 -> 34069733 | K8: =SUM(H8:J8) -> 58236557 | L8: =$C7*L6 -> 15253434 | M8: =$C7*M6 -> 0 | N8: =$C7*N6 -> 0 | O8: =SUM(L8:N8) -> 15253434 | P8: =$C7*P6 -> 0 | Q8: =$C7*Q6 -> 0 | R8: =$C7*R6 -> 0 | S8: =SUM(P8:R8) -> 0 | T8: =G8+K8+O8+S8 -> 87021770
D13: FY 2025
D14: MINIMUM | E14: ACTUAL | F14: FORECAST | G14: EXPECTED total
B15: dozens | C15: #
B16: units | C16: #
