Workbook

Sheet input Licensee sales
AF1: 1447.6657
E2: =SUM(E5:E4930) -> 14982.584 | F2: =SUM(F5:F4929) -> 3.0262652e+08 | G2: =SUM(G5:G4930) -> 22213.506 | H2: =SUM(H5:H4929) -> 4.7951415e+08 | I2: =SUM(I5:I4930) -> 19865.003 | J2: =SUM(J5:J4929) -> 4.3778361e+08 | K2: =SUM(K5:K4930) -> 30709.589 | L2: =SUM(L5:L4929) -> 7.039591e+08 | M2: =SUM(M5:M4930) -> 19682.843 | N2: =SUM(N5:N4929) -> 4.6500257e+08 | O2: =SUM(O5:O4930) -> 19497.333 | P2: =SUM(P5:P4929) -> 4.8842752e+08 | Q2: =SUM(Q5:Q4930) -> 15145.169 | R2: =SUM(R5:R4929) -> 3.6582624e+08 | S2: =SUM(S5:S4930) -> 0 | T2: =SUM(T5:T4929) -> 0 | U2: =SUM(U5:U4930) -> 0 | V2: =SUM(V5:V4929) -> 0 | W2: =SUM(W5:W4930) -> 0 | X2: =SUM(X5:X4929) -> 0 | Y2: =SUM(Y5:Y4930) -> 0 | Z2: =SUM(Z5:Z4929) -> 0 | AA2: =SUM(AA5:AA4929) -> 0 | AB2: =SUM(AB5:AB4929) -> 0 | AC2: =SUM(AC5:AC4930) -> 142096.03 | AD2: =SUM(AD5:AD4929) -> 3.2431397e+09 | AF2: 1408.9662
E3: units | F3: amounts | G3: units | H3: amounts | I3: units | J3: amounts | K3: units | L3: amounts | M3: units | N3: amounts | O3: units | P3: amounts | Q3: units | R3: amounts | S3: units | T3: amounts | U3: units | V3: amounts | W3: units | X3: amounts | Y3: units | Z3: amounts | AA3: units | AB3: amounts | AF3: 1382.7578
A4: Customer | B4: City / Province | C4: Store Type | D4: Product group | E4: 46023 | G4: 46054 | I4: 46082 | K4: 46113 | M4: 46143 | O4: 46174 | Q4: 46204 | S4: 46235 | U4: 46266 | W4: 46296 | Y4: 46327 | AA4: 46357 | AC4: YTD_Units | AD4: YTD_Sales | AF4: =(AF1+AF2+AF3)/3 -> 1413.1299 | AH4: =(AH1+AH2+AH3)/3 -> 0 | AJ4: =(AJ1+AJ2+AJ3)/3 -> 0 | AL4: =(AL1+AL2+AL3)/3 -> 0
A5: DABRA S.A. | B5: Cap Fed | C5: Multibrand | D5: LW | E5: -29.333 | F5: -666772.32 | G5: 6029 | H5: 1.2503203e+08 | I5: 4501 | J5: 85375575 | K5: 9749.5 | L5: 2.1910437e+08 | M5: 5282 | N5: 1.2235736e+08 | O5: 3035.75 | P5: 72362393 | Q5: 3135 | R5: 74479596 | AC5: =AA5+Y5+W5+U5+S5+Q5+O5+M5+K5+I5+G5+E5 -> 31702.917 | AD5: =AB5+Z5+X5+V5+T5+R5+P5+N5+L5+J5+H5+F5 -> 6.9804456e+08 | AE5: =E5+G5+I5 -> 10500.667 | AF5: =(F5+H5+J5)/$AF$4 -> 148422.9 | AG5: =K5+M5+O5 -> 18067.25 | AH5: =(L5+N5+P5)/$AH$4 -> #DIV/0! | AI5: =U5+S5+Q5 -> 3135 | AJ5: =(V5+T5+R5)/$AJ$4 -> #DIV/0! | AK5: =W5+Y5+AA5 -> 0 | AL5: =(X5+Z5+AB5)/$AL$4 -> #DIV/0!
A6: FALCON ESTEBAN LECINA | B6: Cap Fed | C6: Multibrand | D6: LW | E6: 36.75 | F6: 1030690.8 | I6: 0 | J6: 0 | AC6: =AA6+Y6+W6+U6+S6+Q6+O6+M6+K6+I6+G6+E6 -> 36.75 | AD6: =AB6+Z6+X6+V6+T6+R6+P6+N6+L6+J6+H6+F6 -> 1030690.8 | AE6: =E6+G6+I6 -> 36.75 | AF6: =(F6+H6+J6)/$AF$4 -> 729.36734 | AG6: =K6+M6+O6 -> 0 | AH6: =(L6+N6+P6)/$AH$4 -> #DIV/0! | AI6: =U6+S6+Q6 -> 0 | AJ6: =(V6+T6+R6)/$AJ$4 -> #DIV/0! | AK6: =W6+Y6+AA6 -> 0 | AL6: =(X6+Z6+AB6)/$AL$4 -> #DIV/0!
A7: JOSE MARIA BRUNO | B7: Cap Fed | C7: Multibrand | D7: LW | K7: 260 | L7: 5821203.8 | O7: 0 | P7: 0 | AC7: =AA7+Y7+W7+U7+S7+Q7+O7+M7+K7+I7+G7+E7 -> 260 | AD7: =AB7+Z7+X7+V7+T7+R7+P7+N7+L7+J7+H7+F7 -> 5821203.8 | AE7: =E7+G7+I7 -> 0 | AF7: =(F7+H7+J7)/$AF$4 -> 0 | AG7: =K7+M7+O7 -> 260 | AH7: =(L7+N7+P7)/$AH$4 -> #DIV/0! | AI7: =U7+S7+Q7 -> 0 | AJ7: =(V7+T7+R7)/$AJ$4 -> #DIV/0! | AK7: =W7+Y7+AA7 -> 0 | AL7: =(X7+Z7+AB7)/$AL$4 -> #DIV/0!
A8: PUMA SPORTS ARGENTINA S.A | B8: Cap Fed | C8: Puma Stores | D8: LW | E8: 6199 | F8: 1.1629085e+08 | G8: 638 | H8: 11211060 | I8: 245.5 | J8: 5788201.6 | K8: 8741 | L8: 1.7934306e+08 | M8: 3555 | N8: 85834356 | O8: 3201.5 | P8: 72878619 | Q8: 130.5 | R8: 2604360 | AC8: =AA8+Y8+W8+U8+S8+Q8+O8+M8+K8+I8+G8+E8 -> 22710.5 | AD8: =AB8+Z8+X8+V8+T8+R8+P8+N8+L8+J8+H8+F8 -> 4.7395051e+08 | AE8: =E8+G8+I8 -> 7082.5 | AF8: =(F8+H8+J8)/$AF$4 -> 94322.619 | AG8: =K8+M8+O8 -> 15497.5 | AH8: =(L8+N8+P8)/$AH$4 -> #DIV/0! | AI8: =U8+S8+Q8 -> 130.5 | AJ8: =(V8+T8+R8)/$AJ$4 -> #DIV/0! | AK8: =W8+Y8+AA8 -> 0 | AL8: =(X8+Z8+AB8)/$AL$4 -> #DIV/0!
A9: ML FULL | B9: Cap Fed | C9: Multibrand | D9: LW | G9: -13.084 | H9: -233674.8 | I9: 1026.417 | J9: 20729133 | K9: 389.001 | L9: 8015969.1 | O9: 226.167 | P9: 5255769.8 | Q9: 95.001 | R9: 2267493.4 | AC9: =AA9+Y9+W9+U9+S9+Q9+O9+M9+K9+I9+G9+E9 -> 1723.502 | AD9: =AB9+Z9+X9+V9+T9+R9+P9+N9+L9+J9+H9+F9 -> 36034690 | AE9: =E9+G9+I9 -> 1013.333 | AF9: =(F9+H9+J9)/$AF$4 -> 14503.591 | AG9: =K9+M9+O9 -> 615.168 | AH9: =(L9+N9+P9)/$AH$4 -> #DIV/0! | AI9: =U9+S9+Q9 -> 95.001 | AJ9: =(V9+T9+R9)/$AJ$4 -> #DIV/0! | AK9: =W9+Y9+AA9 -> 0 | AL9: =(X9+Z9+AB9)/$AL$4 -> #DIV/0!
A10: COSANELLI ANIBAL | B10: Cap Fed | C10: Multibrand | D10: LW | G10: 126 | H10: 3650176.8 | I10: 106 | J10: 2954880 | K10: 39 | L10: 932239.2 | O10: 90 | P10: 2602893.6 | Q10: 28 | R10: 688034.56 | AC10: =AA10+Y10+W10+U10+S10+Q10+O10+M10+K10+I10+G10+E10 -> 389 | AD10: =AB10+Z10+X10+V10+T10+R10+P10+N10+L10+J10+H10+F10 -> 10828224 | AE10: =E10+G10+I10 -> 232 | AF10: =(F10+H10+J10)/$AF$4 -> 4674.062 | AG10: =K10+M10+O10 -> 129 | AH10: =(L10+N10+P10)/$AH$4 -> #DIV/0! | AI10: =U10+S10+Q10 -> 28 | AJ10: =(V10+T10+R10)/$AJ$4 -> #DIV/0! | AK10: =W10+Y10+AA10 -> 0 | AL10: =(X10+Z10+AB10)/$AL$4 -> #DIV/0!
A11: GRAELLS NELSON ANTONIO | B11: Cap Fed | C11: Multibrand | D11: LW | G11: 785.5 | H11: 17327990 | I11: 271.5 | J11: 5825337.3 | K11: 1056 | L11: 25499208 | M11: 351 | N11: 8759887 | O11: 457.5 | P11: 11679518 | Q11: 695.5 | R11: 17042507 | AC11: =AA11+Y11+W11+U11+S11+Q11+O11+M11+K11+I11+G11+E11 -> 3617 | AD11: =AB11+Z11+X11+V11+T11+R11+P11+N11+L11+J11+H11+F11 -> 86134447 | AE11: =E11+G11+I11 -> 1057 | AF11: =(F11+H11+J11)/$AF$4 -> 16384.429 | AG11: =K11+M11+O11 -> 1864.5 | AH11: =(L11+N11+P11)/$AH$4 -> #DIV/0! | AI11: =U11+S11+Q11 -> 695.5 | AJ11: =(V11+T11+R11)/$AJ$4 -> #DIV/0! | AK11: =W11+Y11+AA11 -> 0 | AL11: =(X11+Z11+AB11)/$AL$4 -> #DIV/0!
A12: LEVI NESTOR | B12: Cap Fed | C12: Multibrand | D12: LW | I12: 9 | J12: 263057.4 | AC12: =AA12+Y12+W12+U12+S12+Q12+O12+M12+K12+I12+G12+E12 -> 9 | AD12: =AB12+Z12+X12+V12+T12+R12+P12+N12+L12+J12+H12+F12 -> 263057.4 | AE12: =E12+G12+I12 -> 9 | AF12: =(F12+H12+J12)/$AF$4 -> 186.15231 | AG12: =K12+M12+O12 -> 0 | AH12: =(L12+N12+P12)/$AH$4 -> #DIV/0! | AI12: =U12+S12+Q12 -> 0 | AJ12: =(V12+T12+R12)/$AJ$4 -> #DIV/0! | AK12: =W12+Y12+AA12 -> 0 | AL12: =(X12+Z12+AB12)/$AL$4 -> #DIV/0!
A13: CARLOS ROSSETTI S.A. | B13: Cap Fed | C13: Multibrand | D13: LW | G13: 2629.5 | H13: 55731766 | I13: 388.5 | J13: 6471501.3 | M13: 1779.5 | N13: 39855163 | AC13: =AA13+Y13+W13+U13+S13+Q13+O13+M13+K13+I13+G13+E13 -> 4797.5 | AD13: =AB13+Z13+X13+V13+T13+R13+P13+N13+L13+J13+H13+F13 -> 1.0205843e+08 | AE13: =E13+G13+I13 -> 3018 | AF13: =(F13+H13+J13)/$AF$4 -> 44018.081 | AG13: =K13+M13+O13 -> 1779.5 | AH13: =(L13+N13+P13)/$AH$4 -> #DIV/0! | AI13: =U13+S13+Q13 -> 0 | AJ13: =(V13+T13+R13)/$AJ$4 -> #DIV/0! | AK13: =W13+Y13+AA13 -> 0 | AL13: =(X13+Z13+AB13)/$AL$4 -> #DIV/0!
A14: DE LUCA HECTOR DAMIAN | B14: Cap Fed | C14: Multibrand | D14: LW | K14: 37.5 | L14: 1022392.8 | AC14: =AA14+Y14+W14+U14+S14+Q14+O14+M14+K14+I14+G14+E14 -> 37.5 | AD14: =AB14+Z14+X14+V14+T14+R14+P14+N14+L14+J14+H14+F14 -> 1022392.8 | AE14: =E14+G14+I14 -> 0 | AF14: =(F14+H14+J14)/$AF$4 -> 0 | AG14: =K14+M14+O14 -> 37.5 | AH14: =(L14+N14+P14)/$AH$4 -> #DIV/0! | AI14: =U14+S14+Q14 -> 0 | AJ14: =(V14+T14+R14)/$AJ$4 -> #DIV/0! | AK14: =W14+Y14+AA14 -> 0 | AL14: =(X14+Z14+AB14)/$AL$4 -> #DIV/0!
A15: FIRST LABEL.SRL | B15: Cap Fed | C15: Multibrand | D15: LW | E15: 126.666 | F15: 2620274.3 | G15: 347.417 | H15: 7246937.9 | I15: 196.75 | J15: 4187642.2 | K15: 307.002 | L15: 7329410.5 | M15: 253.833 | N15: 5600952.2 | O15: 65.75 | P15: 1715604.3 | Q15: 205.501 | R15: 4716714.2 | AC15: =AA15+Y15+W15+U15+S15+Q15+O15+M15+K15+I15+G15+E15 -> 1502.919 | AD15: =AB15+Z15+X15+V15+T15+R15+P15+N15+L15+J15+H15+F15 -> 33417536 | AE15: =E15+G15+I15 -> 670.833 | AF15: =(F15+H15+J15)/$AF$4 -> 9945.904 | AG15: =K15+M15+O15 -> 626.585 | AH15: =(L15+N15+P15)/$AH$4 -> #DIV/0! | AI15: =U15+S15+Q15 -> 205.501 | AJ15: =(V15+T15+R15)/$AJ$4 -> #DIV/0! | AK15: =W15+Y15+AA15 -> 0 | AL15: =(X15+Z15+AB15)/$AL$4 -> #DIV/0!
A16: DAVID COMIZZO DEPORTES S.C | B16: NEA | C16: Multibrand | D16: LW | G16: 122.5 | H16: 2881775 | I16: 77.5 | J16: 1965678.9 | M16: 94.5 | N16: 2351060.2 | Q16: 58.25 | R16: 1511801.4 | AC16: =AA16+Y16+W16+U16+S16+Q16+O16+M16+K16+I16+G16+E16 -> 352.75 | AD16: =AB16+Z16+X16+V16+T16+R16+P16+N16+L16+J16+H16+F16 -> 8710315.5 | AE16: =E16+G16+I16 -> 200 | AF16: =(F16+H16+J16)/$AF$4 -> 3430.2961 | AG16: =K16+M16+O16 -> 94.5 | AH16: =(L16+N16+P16)/$AH$4 -> #DIV/0! | AI16: =U16+S16+Q16 -> 58.25 | AJ16: =(V16+T16+R16)/$AJ$4 -> #DIV/0! | AK16: =W16+Y16+AA16 -> 0 | AL16: =(X16+Z16+AB16)/$AL$4 -> #DIV/0!
A17: LONGHI MARCELO | B17: NEA | C17: Multibrand | D17: LW | G17: 33.75 | H17: 698862.65 | K17: 31.25 | L17: 733961.58 | O17: 31 | P17: 758448.24 | Q17: 15.25 | R17: 419633.13 | AC17: =AA17+Y17+W17+U17+S17+Q17+O17+M17+K17+I17+G17+E17 -> 111.25 | AD17: =AB17+Z17+X17+V17+T17+R17+P17+N17+L17+J17+H17+F17 -> 2610905.6 | AE17: =E17+G17+I17 -> 33.75 | AF17: =(F17+H17+J17)/$AF$4 -> 494.54947 | AG17: =K17+M17+O17 -> 62.25 | AH17: =(L17+N17+P17)/$AH$4 -> #DIV/0! | AI17: =U17+S17+Q17 -> 15.25 | AJ17: =(V17+T17+R17)/$AJ$4 -> #DIV/0! | AK17: =W17+Y17+AA17 -> 0 | AL17: =(X17+Z17+AB17)/$AL$4 -> #DIV/0!
A18: OSOPPO S.A. | B18: NEA | C18: Multibrand | D18: LW | G18: -1.5 | H18: -33259.08 | I18: 46 | J18: 1223937.5 | O18: 29 | P18: 786654.81 | AC18: =AA18+Y18+W18+U18+S18+Q18+O18+M18+K18+I18+G18+E18 -> 73.5 | AD18: =AB18+Z18+X18+V18+T18+R18+P18+N18+L18+J18+H18+F18 -> 1977333.2 | AE18: =E18+G18+I18 -> 44.5 | AF18: =(F18+H18+J18)/$AF$4 -> 842.58244 | AG18: =K18+M18+O18 -> 29 | AH18: =(L18+N18+P18)/$AH$4 -> #DIV/0! | AI18: =U18+S18+Q18 -> 0 | AJ18: =(V18+T18+R18)/$AJ$4 -> #DIV/0! | AK18: =W18+Y18+AA18 -> 0 | AL18: =(X18+Z18+AB18)/$AL$4 -> #DIV/0!
A19: SIAN S.A. | B19: NEA | C19: Multibrand | D19: LW | O19: 180 | P19: 4736397.8 | AC19: =AA19+Y19+W19+U19+S19+Q19+O19+M19+K19+I19+G19+E19 -> 180 | AD19: =AB19+Z19+X19+V19+T19+R19+P19+N19+L19+J19+H19+F19 -> 4736397.8 | AE19: =E19+G19+I19 -> 0 | AF19: =(F19+H19+J19)/$AF$4 -> 0 | AG19: =K19+M19+O19 -> 180 | AH19: =(L19+N19+P19)/$AH$4 -> #DIV/0! | AI19: =U19+S19+Q19 -> 0 | AJ19: =(V19+T19+R19)/$AJ$4 -> #DIV/0! | AK19: =W19+Y19+AA19 -> 0 | AL19: =(X19+Z19+AB19)/$AL$4 -> #DIV/0!
A20: KADIMA S.A. | B20: NEA | C20: Multibrand | D20: LW | K20: 340 | L20: 8853405.8 | O20: 353 | P20: 10007349 | Q20: 66 | R20: 1916194.3 | AC20: =AA20+Y20+W20+U20+S20+Q20+O20+M20+K20+I20+G20+E20 -> 759 | AD20: =AB20+Z20+X20+V20+T20+R20+P20+N20+L20+J20+H20+F20 -> 20776949 | AE20: =E20+G20+I20 -> 0 | AF20: =(F20+H20+J20)/$AF$4 -> 0 | AG20: =K20+M20+O20 -> 693 | AH20: =(L20+N20+P20)/$AH$4 -> #DIV/0! | AI20: =U20+S20+Q20 -> 66 | AJ20: =(V20+T20+R20)/$AJ$4 -> #DIV/0! | AK20: =W20+Y20+AA20 -> 0 | AL20: =(X20+Z20+AB20)/$AL$4 -> #DIV/0!
A21: MARTI JUAN MARTIN | B21: NEA | C21: Multibrand | D21: LW | G21: 19.75 | H21: 467648.79 | I21: 17.5 | J21: 418049.49 | O21: 18.75 | P21: 501777.27 | AC21: =AA21+Y21+W21+U21+S21+Q21+O21+M21+K21+I21+G21+E21 -> 56 | AD21: =AB21+Z21+X21+V21+T21+R21+P21+N21+L21+J21+H21+F21 -> 1387475.6 | AE21: =E21+G21+I21 -> 37.25 | AF21: =(F21+H21+J21)/$AF$4 -> 626.76353 | AG21: =K21+M21+O21 -> 18.75 | AH21: =(L21+N21+P21)/$AH$4 -> #DIV/0! | AI21: =U21+S21+Q21 -> 0 | AJ21: =(V21+T21+R21)/$AJ$4 -> #DIV/0! | AK21: =W21+Y21+AA21 -> 0 | AL21: =(X21+Z21+AB21)/$AL$4 -> #DIV/0!
A22: CENTRO DEPORTES S.R.L. | B22: NEA | C22: Multibrand | D22: LW | K22: 48 | L22: 1157419.5 | O22: 27 | P22: 807428.07 | AC22: =AA22+Y22+W22+U22+S22+Q22+O22+M22+K22+I22+G22+E22 -> 75 | AD22: =AB22+Z22+X22+V22+T22+R22+P22+N22+L22+J22+H22+F22 -> 1964847.6 | AE22: =E22+G22+I22 -> 0 | AF22: =(F22+H22+J22)/$AF$4 -> 0 | AG22: =K22+M22+O22 -> 75 | AH22: =(L22+N22+P22)/$AH$4 -> #DIV/0! | AI22: =U22+S22+Q22 -> 0 | AJ22: =(V22+T22+R22)/$AJ$4 -> #DIV/0! | AK22: =W22+Y22+AA22 -> 0 | AL22: =(X22+Z22+AB22)/$AL$4 -> #DIV/0!
A23: Von Muhlinen Santiago | B23: NEA | C23: Multibrand | D23: LW | K23: 63 | L23: 1418112.3 | Q23: 28 | R23: 764818.09 | AC23: =AA23+Y23+W23+U23+S23+Q23+O23+M23+K23+I23+G23+E23 -> 91 | AD23: =AB23+Z23+X23+V23+T23+R23+P23+N23+L23+J23+H23+F23 -> 2182930.4 | AE23: =E23+G23+I23 -> 0 | AF23: =(F23+H23+J23)/$AF$4 -> 0 | AG23: =K23+M23+O23 -> 63 | AH23: =(L23+N23+P23)/$AH$4 -> #DIV/0! | AI23: =U23+S23+Q23 -> 28 | AJ23: =(V23+T23+R23)/$AJ$4 -> #DIV/0! | AK23: =W23+Y23+AA23 -> 0 | AL23: =(X23+Z23+AB23)/$AL$4 -> #DIV/0!
A24: CASA DEL PUEBLO S.A | B24: NEA | C24: Multibrand | D24: LW | G24: 126.5 | H24: 2717783.8 | K24: 137 | L24: 3319780.7 | AC24: =AA24+Y24+W24+U24+S24+Q24+O24+M24+K24+I24+G24+E24 -> 263.5 | AD24: =AB24+Z24+X24+V24+T24+R24+P24+N24+L24+J24+H24+F24 -> 6037564.5 | AE24: =E24+G24+I24 -> 126.5 | AF24: =(F24+H24+J24)/$AF$4 -> 1923.2371 | AG24: =K24+M24+O24 -> 137 | AH24: =(L24+N24+P24)/$AH$4 -> #DIV/0! | AI24: =U24+S24+Q24 -> 0 | AJ24: =(V24+T24+R24)/$AJ$4 -> #DIV/0! | AK24: =W24+Y24+AA24 -> 0 | AL24: =(X24+Z24+AB24)/$AL$4 -> #DIV/0!
A25: VALERA SANDRA PATRICIA | B25: NEA | C25: Multibrand | D25: LW | I25: 12.5 | J25: 345026.41 | AC25: =AA25+Y25+W25+U25+S25+Q25+O25+M25+K25+I25+G25+E25 -> 12.5 | AD25: =AB25+Z25+X25+V25+T25+R25+P25+N25+L25+J25+H25+F25 -> 345026.41 | AE25: =E25+G25+I25 -> 12.5 | AF25: =(F25+H25+J25)/$AF$4 -> 244.1576 | AG25: =K25+M25+O25 -> 0 | AH25: =(L25+N25+P25)/$AH$4 -> #DIV/0! | AI25: =U25+S25+Q25 -> 0 | AJ25: =(V25+T25+R25)/$AJ$4 -> #DIV/0! | AK25: =W25+Y25+AA25 -> 0 | AL25: =(X25+Z25+AB25)/$AL$4 -> #DIV/0!
A26: IMPACTO DEPORTES S.R.L. | B26: NEA | C26: Multibrand | D26: LW | K26: 21.75 | L26: 570783.19 | O26: 18.5 | P26: 503842.41 | AC26: =AA26+Y26+W26+U26+S26+Q26+O26+M26+K26+I26+G26+E26 -> 40.25 | AD26: =AB26+Z26+X26+V26+T26+R26+P26+N26+L26+J26+H26+F26 -> 1074625.6 | AE26: =E26+G26+I26 -> 0 | AF26: =(F26+H26+J26)/$AF$4 -> 0 | AG26: =K26+M26+O26 -> 40.25 | AH26: =(L26+N26+P26)/$AH$4 -> #DIV/0! | AI26: =U26+S26+Q26 -> 0 | AJ26: =(V26+T26+R26)/$AJ$4 -> #DIV/0! | AK26: =W26+Y26+AA26 -> 0 | AL26: =(X26+Z26+AB26)/$AL$4 -> #DIV/0!
A27: SANTIAGO VON MUHLIENEN | B27: NEA | C27: Multibrand | D27: LW | I27: 100.5 | J27: 2524583.6 | O27: 53 | P27: 1387539.8 | AC27: =AA27+Y27+W27+U27+S27+Q27+O27+M27+K27+I27+G27+E27 -> 153.5 | AD27: =AB27+Z27+X27+V27+T27+R27+P27+N27+L27+J27+H27+F27 -> 3912123.4 | AE27: =E27+G27+I27 -> 100.5 | AF27: =(F27+H27+J27)/$AF$4 -> 1786.5191 | AG27: =K27+M27+O27 -> 53 | AH27: =(L27+N27+P27)/$AH$4 -> #DIV/0! | AI27: =U27+S27+Q27 -> 0 | AJ27: =(V27+T27+R27)/$AJ$4 -> #DIV/0! | AK27: =W27+Y27+AA27 -> 0 | AL27: =(X27+Z27+AB27)/$AL$4 -> #DIV/0!
A28: FACTORY SPORT S.A. | B28: GBA | C28: Multibrand | D28: LW | M28: 114 | N28: 2836238.9 | AC28: =AA28+Y28+W28+U28+S28+Q28+O28+M28+K28+I28+G28+E28 -> 114 | AD28: =AB28+Z28+X28+V28+T28+R28+P28+N28+L28+J28+H28+F28 -> 2836238.9 | AE28: =E28+G28+I28 -> 0 | AF28: =(F28+H28+J28)/$AF$4 -> 0 | AG28: =K28+M28+O28 -> 114 | AH28: =(L28+N28+P28)/$AH$4 -> #DIV/0! | AI28: =U28+S28+Q28 -> 0 | AJ28: =(V28+T28+R28)/$AJ$4 -> #DIV/0! | AK28: =W28+Y28+AA28 -> 0 | AL28: =(X28+Z28+AB28)/$AL$4 -> #DIV/0!
A29: MARJUSVALE S.A. | B29: GBA | C29: Multibrand | D29: LW | E29: 26 | F29: 646566.3 | K29: 17 | L29: 440832.24 | O29: 6.5 | P29: 169684.64 | Q29: -1 | R29: -22262.9 | AC29: =AA29+Y29+W29+U29+S29+Q29+O29+M29+K29+I29+G29+E29 -> 48.5 | AD29: =AB29+Z29+X29+V29+T29+R29+P29+N29+L29+J29+H29+F29 -> 1234820.3 | AE29: =E29+G29+I29 -> 26 | AF29: =(F29+H29+J29)/$AF$4 -> 457.54201 | AG29: =K29+M29+O29 -> 23.5 | AH29: =(L29+N29+P29)/$AH$4 -> #DIV/0! | AI29: =U29+S29+Q29 -> -1 | AJ29: =(V29+T29+R29)/$AJ$4 -> #DIV/0! | AK29: =W29+Y29+AA29 -> 0 | AL29: =(X29+Z29+AB29)/$AL$4 -> #DIV/0!
A30: O.A. DEPORTES S.R.L. | B30: GBA | C30: Multibrand | D30: LW | G30: 55 | H30: 1719005.2 | M30: 62 | N30: 1961800.7 | O30: 64 | P30: 1764500 | AC30: =AA30+Y30+W30+U30+S30+Q30+O30+M30+K30+I30+G30+E30 -> 181 | AD30: =AB30+Z30+X30+V30+T30+R30+P30+N30+L30+J30+H30+F30 -> 5445305.9 | AE30: =E30+G30+I30 -> 55 | AF30: =(F30+H30+J30)/$AF$4 -> 1216.4523 | AG30: =K30+M30+O30 -> 126 | AH30: =(L30+N30+P30)/$AH$4 -> #DIV/0! | AI30: =U30+S30+Q30 -> 0 | AJ30: =(V30+T30+R30)/$AJ$4 -> #DIV/0! | AK30: =W30+Y30+AA30 -> 0 | AL30: =(X30+Z30+AB30)/$AL$4 -> #DIV/0!
A31: FORTALEZA EXTREMA S.A. | B31: GBA | C31: Multibrand | D31: LW | I31: 25 | J31: 671406.43 | M31: 112 | N31: 2969277.6 | AC31: =AA31+Y31+W31+U31+S31+Q31+O31+M31+K31+I31+G31+E31 -> 137 | AD31: =AB31+Z31+X31+V31+T31+R31+P31+N31+L31+J31+H31+F31 -> 3640684 | AE31: =E31+G31+I31 -> 25 | AF31: =(F31+H31+J31)/$AF$4 -> 475.12011 | AG31: =K31+M31+O31 -> 112 | AH31: =(L31+N31+P31)/$AH$4 -> #DIV/0! | AI31: =U31+S31+Q31 -> 0 | AJ31: =(V31+T31+R31)/$AJ$4 -> #DIV/0! | AK31: =W31+Y31+AA31 -> 0 | AL31: =(X31+Z31+AB31)/$AL$4 -> #DIV/0!
A32: LAGUARDIA FRANCO | B32: GBA | C32: Multibrand | D32: LW | I32: 30 | J32: 1061457 | AC32: =AA32+Y32+W32+U32+S32+Q32+O32+M32+K32+I32+G32+E32 -> 30 | AD32: =AB32+Z32+X32+V32+T32+R32+P32+N32+L32+J32+H32+F32 -> 1061457 | AE32: =E32+G32+I32 -> 30 | AF32: =(F32+H32+J32)/$AF$4 -> 751.13901 | AG32: =K32+M32+O32 -> 0 | AH32: =(L32+N32+P32)/$AH$4 -> #DIV/0! | AI32: =U32+S32+Q32 -> 0 | AJ32: =(V32+T32+R32)/$AJ$4 -> #DIV/0! | AK32: =W32+Y32+AA32 -> 0 | AL32: =(X32+Z32+AB32)/$AL$4 -> #DIV/0!
A33: CRAVERO ADIAN GUSTAVO | B33: GBA | C33: Multibrand | D33: LW | E33: 48.5 | F33: 1128643.2 | AC33: =AA33+Y33+W33+U33+S33+Q33+O33+M33+K33+I33+G33+E33 -> 48.5 | AD33: =AB33+Z33+X33+V33+T33+R33+P33+N33+L33+J33+H33+F33 -> 1128643.2 | AE33: =E33+G33+I33 -> 48.5 | AF33: =(F33+H33+J33)/$AF$4 -> 798.68326 | AG33: =K33+M33+O33 -> 0 | AH33: =(L33+N33+P33)/$AH$4 -> #DIV/0! | AI33: =U33+S33+Q33 -> 0 | AJ33: =(V33+T33+R33)/$AJ$4 -> #DIV/0! | AK33: =W33+Y33+AA33 -> 0 | AL33: =(X33+Z33+AB33)/$AL$4 -> #DIV/0!
A34: ANNEX | B34: GBA | C34: Multibrand | D34: LW | Q34: 652 | R34: 18418572 | AC34: =AA34+Y34+W34+U34+S34+Q34+O34+M34+K34+I34+G34+E34 -> 652 | AD34: =AB34+Z34+X34+V34+T34+R34+P34+N34+L34+J34+H34+F34 -> 18418572 | AE34: =E34+G34+I34 -> 0 | AF34: =(F34+H34+J34)/$AF$4 -> 0 | AG34: =K34+M34+O34 -> 0 | AH34: =(L34+N34+P34)/$AH$4 -> #DIV/0! | AI34: =U34+S34+Q34 -> 652 | AJ34: =(V34+T34+R34)/$AJ$4 -> #DIV/0! | AK34: =W34+Y34+AA34 -> 0 | AL34: =(X34+Z34+AB34)/$AL$4 -> #DIV/0!
A35: ZARCAL S.A. | B35: GBA | C35: Multibrand | D35: LW | E35: 208.5 | F35: 4397474.3 | O35: 140 | P35: 3633494.3 | Q35: 45 | R35: 1215149.8 | AC35: =AA35+Y35+W35+U35+S35+Q35+O35+M35+K35+I35+G35+E35 -> 393.5 | AD35: =AB35+Z35+X35+V35+T35+R35+P35+N35+L35+J35+H35+F35 -> 9246118.4 | AE35: =E35+G35+I35 -> 208.5 | AF35: =(F35+H35+J35)/$AF$4 -> 3111.8684 | AG35: =K35+M35+O35 -> 140 | AH35: =(L35+N35+P35)/$AH$4 -> #DIV/0! | AI35: =U35+S35+Q35 -> 45 | AJ35: =(V35+T35+R35)/$AJ$4 -> #DIV/0! | AK35: =W35+Y35+AA35 -> 0 | AL35: =(X35+Z35+AB35)/$AL$4 -> #DIV/0!
A36: DE GRUTOLLA DOMINGO | B36: GBA | C36: Multibrand | D36: LW | O36: 46 | P36: 1306060.2 | AC36: =AA36+Y36+W36+U36+S36+Q36+O36+M36+K36+I36+G36+E36 -> 46 | AD36: =AB36+Z36+X36+V36+T36+R36+P36+N36+L36+J36+H36+F36 -> 1306060.2 | AE36: =E36+G36+I36 -> 0 | AF36: =(F36+H36+J36)/$AF$4 -> 0 | AG36: =K36+M36+O36 -> 46 | AH36: =(L36+N36+P36)/$AH$4 -> #DIV/0! | AI36: =U36+S36+Q36 -> 0 | AJ36: =(V36+T36+R36)/$AJ$4 -> #DIV/0! | AK36: =W36+Y36+AA36 -> 0 | AL36: =(X36+Z36+AB36)/$AL$4 -> #DIV/0!
A37: BLOISE GENARO Y BLOISE ANGEL SOCIEDAD | B37: GBA | C37: Multibrand | D37: LW | G37: 748.833 | H37: 18970197 | I37: 854 | J37: 19100316 | M37: 914 | N37: 21088769 | O37: 95.5 | P37: 2325962 | AC37: =AA37+Y37+W37+U37+S37+Q37+O37+M37+K37+I37+G37+E37 -> 2612.333 | AD37: =AB37+Z37+X37+V37+T37+R37+P37+N37+L37+J37+H37+F37 -> 61485244 | AE37: =E37+G37+I37 -> 1602.833 | AF37: =(F37+H37+J37)/$AF$4 -> 26940.562 | AG37: =K37+M37+O37 -> 1009.5 | AH37: =(L37+N37+P37)/$AH$4 -> #DIV/0! | AI37: =U37+S37+Q37 -> 0 | AJ37: =(V37+T37+R37)/$AJ$4 -> #DIV/0! | AK37: =W37+Y37+AA37 -> 0 | AL37: =(X37+Z37+AB37)/$AL$4 -> #DIV/0!
A38: ESTAFO JOSE OSVALDO | B38: GBA | C38: Multibrand | D38: LW | E38: 7.5 | F38: 208442.4 | AC38: =AA38+Y38+W38+U38+S38+Q38+O38+M38+K38+I38+G38+E38 -> 7.5 | AD38: =AB38+Z38+X38+V38+T38+R38+P38+N38+L38+J38+H38+F38 -> 208442.4 | AE38: =E38+G38+I38 -> 7.5 | AF38: =(F38+H38+J38)/$AF$4 -> 147.50406 | AG38: =K38+M38+O38 -> 0 | AH38: =(L38+N38+P38)/$AH$4 -> #DIV/0! | AI38: =U38+S38+Q38 -> 0 | AJ38: =(V38+T38+R38)/$AJ$4 -> #DIV/0! | AK38: =W38+Y38+AA38 -> 0 | AL38: =(X38+Z38+AB38)/$AL$4 -> #DIV/0!
A39: DE GRUTTOLA JESUS Y JAVIER S.H. | B39: GBA | C39: Multibrand | D39: LW | K39: 46 | L39: 1167914.4 | AC39: =AA39+Y39+W39+U39+S39+Q39+O39+M39+K39+I39+G39+E39 -> 46 | AD39: =AB39+Z39+X39+V39+T39+R39+P39+N39+L39+J39+H39+F39 -> 1167914.4 | AE39: =E39+G39+I39 -> 0 | AF39: =(F39+H39+J39)/$AF$4 -> 0 | AG39: =K39+M39+O39 -> 46 | AH39: =(L39+N39+P39)/$AH$4 -> #DIV/0! | AI39: =U39+S39+Q39 -> 0 | AJ39: =(V39+T39+R39)/$AJ$4 -> #DIV/0! | AK39: =W39+Y39+AA39 -> 0 | AL39: =(X39+Z39+AB39)/$AL$4 -> #DIV/0!
A40: GOMEZ MIGUEL ANGEL | B40: GBA | C40: Multibrand | D40: LW | M40: 47 | N40: 1199544.5 | O40: 8 | P40: 214060.97 | AC40: =AA40+Y40+W40+U40+S40+Q40+O40+M40+K40+I40+G40+E40 -> 55 | AD40: =AB40+Z40+X40+V40+T40+R40+P40+N40+L40+J40+H40+F40 -> 1413605.5 | AE40: =E40+G40+I40 -> 0 | AF40: =(F40+H40+J40)/$AF$4 -> 0 | AG40: =K40+M40+O40 -> 55 | AH40: =(L40+N40+P40)/$AH$4 -> #DIV/0! | AI40: =U40+S40+Q40 -> 0 | AJ40: =(V40+T40+R40)/$AJ$4 -> #DIV/0! | AK40: =W40+Y40+AA40 -> 0 | AL40: =(X40+Z40+AB40)/$AL$4 -> #DIV/0!
...

Sheet input Licensee ooh
A1: Total | J1: =SUM(J36:J5000) -> 0 | K1: =SUM(K36:K5000) -> 0 | L1: =SUM(L4:L5000) -> 0 | M1: =SUM(M4:M5000) -> 0 | N1: =SUM(N4:N5000) -> 0 | O1: =SUM(O4:O5000) -> 0 | P1: =SUM(P4:P5000) -> 0 | Q1: =SUM(Q4:Q5000) -> 0 | R1: =SUM(R4:R5000) -> 0 | S1: =SUM(S4:S5000) -> 0 | ... AI1: =SUM(AI4:AI5000) -> #REF!
J2: units | K2: amounts | L2: units | M2: amounts | N2: units | O2: amounts | P2: units | Q2: amounts | R2: units | S2: amounts | T2: units | U2: amounts | V2: units | W2: amounts | X2: units | Y2: amounts | Z2: units | AA2: amounts | AB2: units | AC2: amounts | AD2: units | AE2: amounts | AF2: units | AG2: amounts
A3: Licencee | B3: Type | C3: Licencee_Country | D3: Currency | E3: Year | F3: Customer | G3: City / Province | H3: Store Type | I3: Product group | J3: 46023 | L3: 46054 | N3: 46082 | P3: 46113 | R3: 46143 | T3: 46174 | V3: 46204 | X3: 46235 | Z3: 46266 | AB3: 46296 | AD3: 46327 | AF3: 46357 | AH3: YTD_Units | AI3: YTD_Sales
A4: Best Sox | B4: 100 | C4: Argentina | D4: ARS | E4: 2015 | AH4: =AF4+AD4+AB4+Z4+X4+V4+T4+R4+P4+N4+L4+'input Licensee sales'!#REF! -> #REF! | AI4: =AG4+AE4+AC4+AA4+Y4+W4+U4+S4+Q4+O4+M4+'input Licensee sales'!#REF! -> #REF!
A5: Best Sox | B5: 100 | C5: Argentina | D5: ARS | E5: 2015 | AH5: =AF5+AD5+AB5+Z5+X5+V5+T5+R5+P5+N5+L5+'input Licensee sales'!#REF! -> #REF! | AI5: =AG5+AE5+AC5+AA5+Y5+W5+U5+S5+Q5+O5+M5+'input Licensee sales'!#REF! -> #REF!
A6: Best Sox | B6: 100 | C6: Argentina | D6: ARS | E6: 2015 | AH6: =AF6+AD6+AB6+Z6+X6+V6+T6+R6+P6+N6+L6+'input Licensee sales'!E5 -> -29.333 | AI6: =AG6+AE6+AC6+AA6+Y6+W6+U6+S6+Q6+O6+M6+'input Licensee sales'!F5 -> -666772.32
A7: Best Sox | B7: 100 | C7: Argentina | D7: ARS | E7: 2015 | AH7: =AF7+AD7+AB7+Z7+X7+V7+T7+R7+P7+N7+L7+'input Licensee sales'!#REF! -> #REF! | AI7: =AG7+AE7+AC7+AA7+Y7+W7+U7+S7+Q7+O7+M7+'input Licensee sales'!#REF! -> #REF!
A8: Best Sox | B8: 100 | C8: Argentina | D8: ARS | E8: 2015 | AH8: =AF8+AD8+AB8+Z8+X8+V8+T8+R8+P8+N8+L8+'input Licensee sales'!#REF! -> #REF! | AI8: =AG8+AE8+AC8+AA8+Y8+W8+U8+S8+Q8+O8+M8+'input Licensee sales'!#REF! -> #REF!
A9: Best Sox | B9: 100 | C9: Argentina | D9: ARS | E9: 2015 | AH9: =AF9+AD9+AB9+Z9+X9+V9+T9+R9+P9+N9+L9+'input Licensee sales'!E6 -> 36.75 | AI9: =AG9+AE9+AC9+AA9+Y9+W9+U9+S9+Q9+O9+M9+'input Licensee sales'!F6 -> 1030690.8
A10: Best Sox | B10: 100 | C10: Argentina | D10: ARS | E10: 2015 | AH10: =AF10+AD10+AB10+Z10+X10+V10+T10+R10+P10+N10+L10+'input Licensee sales'!E7 -> 0 | AI10: =AG10+AE10+AC10+AA10+Y10+W10+U10+S10+Q10+O10+M10+'input Licensee sales'!F7 -> 0
A11: Best Sox | B11: 100 | C11: Argentina | D11: ARS | E11: 2015 | AH11: =AF11+AD11+AB11+Z11+X11+V11+T11+R11+P11+N11+L11+'input Licensee sales'!#REF! -> #REF! | AI11: =AG11+AE11+AC11+AA11+Y11+W11+U11+S11+Q11+O11+M11+'input Licensee sales'!#REF! -> #REF!
A12: Best Sox | B12: 100 | C12: Argentina | D12: ARS | E12: 2015 | AH12: =AF12+AD12+AB12+Z12+X12+V12+T12+R12+P12+N12+L12+'input Licensee sales'!E8 -> 6199 | AI12: =AG12+AE12+AC12+AA12+Y12+W12+U12+S12+Q12+O12+M12+'input Licensee sales'!F8 -> 1.1629085e+08
A13: Best Sox | B13: 100 | C13: Argentina | D13: ARS | E13: 2015 | AH13: =AF13+AD13+AB13+Z13+X13+V13+T13+R13+P13+N13+L13+'input Licensee sales'!#REF! -> #REF! | AI13: =AG13+AE13+AC13+AA13+Y13+W13+U13+S13+Q13+O13+M13+'input Licensee sales'!#REF! -> #REF!
A14: Best Sox | B14: 100 | C14: Argentina | D14: ARS | E14: 2015 | AH14: =AF14+AD14+AB14+Z14+X14+V14+T14+R14+P14+N14+L14+'input Licensee sales'!E9 -> 0 | AI14: =AG14+AE14+AC14+AA14+Y14+W14+U14+S14+Q14+O14+M14+'input Licensee sales'!F9 -> 0
A15: Best Sox | B15: 100 | C15: Argentina | D15: ARS | E15: 2015 | AH15: =AF15+AD15+AB15+Z15+X15+V15+T15+R15+P15+N15+L15+'input Licensee sales'!#REF! -> #REF! | AI15: =AG15+AE15+AC15+AA15+Y15+W15+U15+S15+Q15+O15+M15+'input Licensee sales'!#REF! -> #REF!
A16: Best Sox | B16: 100 | C16: Argentina | D16: ARS | E16: 2015 | AH16: =AF16+AD16+AB16+Z16+X16+V16+T16+R16+P16+N16+L16+'input Licensee sales'!#REF! -> #REF! | AI16: =AG16+AE16+AC16+AA16+Y16+W16+U16+S16+Q16+O16+M16+'input Licensee sales'!#REF! -> #REF!
A17: Best Sox | B17: 100 | C17: Argentina | D17: ARS | E17: 2015 | AH17: =AF17+AD17+AB17+Z17+X17+V17+T17+R17+P17+N17+L17+'input Licensee sales'!#REF! -> #REF! | AI17: =AG17+AE17+AC17+AA17+Y17+W17+U17+S17+Q17+O17+M17+'input Licensee sales'!#REF! -> #REF!
A18: Best Sox | B18: 100 | C18: Argentina | D18: ARS | E18: 2015 | AH18: =AF18+AD18+AB18+Z18+X18+V18+T18+R18+P18+N18+L18+'input Licensee sales'!#REF! -> #REF! | AI18: =AG18+AE18+AC18+AA18+Y18+W18+U18+S18+Q18+O18+M18+'input Licensee sales'!#REF! -> #REF!
A19: Best Sox | B19: 100 | C19: Argentina | D19: ARS | E19: 2015 | AH19: =AF19+AD19+AB19+Z19+X19+V19+T19+R19+P19+N19+L19+'input Licensee sales'!#REF! -> #REF! | AI19: =AG19+AE19+AC19+AA19+Y19+W19+U19+S19+Q19+O19+M19+'input Licensee sales'!#REF! -> #REF!
A20: Best Sox | B20: 100 | C20: Argentina | D20: ARS | E20: 2015 | AH20: =AF20+AD20+AB20+Z20+X20+V20+T20+R20+P20+N20+L20+'input Licensee sales'!E10 -> 0 | AI20: =AG20+AE20+AC20+AA20+Y20+W20+U20+S20+Q20+O20+M20+'input Licensee sales'!F10 -> 0
A21: Best Sox | B21: 100 | C21: Argentina | D21: ARS | E21: 2015 | AH21: =AF21+AD21+AB21+Z21+X21+V21+T21+R21+P21+N21+L21+'input Licensee sales'!E11 -> 0 | AI21: =AG21+AE21+AC21+AA21+Y21+W21+U21+S21+Q21+O21+M21+'input Licensee sales'!F11 -> 0
A22: Best Sox | B22: 100 | C22: Argentina | D22: ARS | E22: 2015 | AH22: =AF22+AD22+AB22+Z22+X22+V22+T22+R22+P22+N22+L22+'input Licensee sales'!E13 -> 0 | AI22: =AG22+AE22+AC22+AA22+Y22+W22+U22+S22+Q22+O22+M22+'input Licensee sales'!F13 -> 0
A23: Best Sox | B23: 100 | C23: Argentina | D23: ARS | E23: 2015 | AH23: =AF23+AD23+AB23+Z23+X23+V23+T23+R23+P23+N23+L23+'input Licensee sales'!E15 -> 126.666 | AI23: =AG23+AE23+AC23+AA23+Y23+W23+U23+S23+Q23+O23+M23+'input Licensee sales'!F15 -> 2620274.3
A24: Best Sox | B24: 100 | C24: Argentina | D24: ARS | E24: 2015 | AH24: =AF24+AD24+AB24+Z24+X24+V24+T24+R24+P24+N24+L24+'input Licensee sales'!E16 -> 0 | AI24: =AG24+AE24+AC24+AA24+Y24+W24+U24+S24+Q24+O24+M24+'input Licensee sales'!F16 -> 0
A25: Best Sox | B25: 100 | C25: Argentina | D25: ARS | E25: 2015 | AH25: =AF25+AD25+AB25+Z25+X25+V25+T25+R25+P25+N25+L25+'input Licensee sales'!E17 -> 0 | AI25: =AG25+AE25+AC25+AA25+Y25+W25+U25+S25+Q25+O25+M25+'input Licensee sales'!F17 -> 0
A26: Best Sox | B26: 100 | C26: Argentina | D26: ARS | E26: 2015 | AH26: =AF26+AD26+AB26+Z26+X26+V26+T26+R26+P26+N26+L26+'input Licensee sales'!E18 -> 0 | AI26: =AG26+AE26+AC26+AA26+Y26+W26+U26+S26+Q26+O26+M26+'input Licensee sales'!F18 -> 0
A27: Best Sox | B27: 100 | C27: Argentina | D27: ARS | E27: 2015 | AH27: =AF27+AD27+AB27+Z27+X27+V27+T27+R27+P27+N27+L27+'input Licensee sales'!E19 -> 0 | AI27: =AG27+AE27+AC27+AA27+Y27+W27+U27+S27+Q27+O27+M27+'input Licensee sales'!F19 -> 0
A28: Best Sox | B28: 100 | C28: Argentina | D28: ARS | E28: 2015 | AH28: =AF28+AD28+AB28+Z28+X28+V28+T28+R28+P28+N28+L28+'input Licensee sales'!E20 -> 0 | AI28: =AG28+AE28+AC28+AA28+Y28+W28+U28+S28+Q28+O28+M28+'input Licensee sales'!F20 -> 0
A29: Best Sox | B29: 100 | C29: Argentina | D29: ARS | E29: 2015 | AH29: =AF29+AD29+AB29+Z29+X29+V29+T29+R29+P29+N29+L29+'input Licensee sales'!#REF! -> #REF! | AI29: =AG29+AE29+AC29+AA29+Y29+W29+U29+S29+Q29+O29+M29+'input Licensee sales'!#REF! -> #REF!
A30: Best Sox | B30: 100 | C30: Argentina | D30: ARS | E30: 2015 | AH30: =AF30+AD30+AB30+Z30+X30+V30+T30+R30+P30+N30+L30+'input Licensee sales'!E21 -> 0 | AI30: =AG30+AE30+AC30+AA30+Y30+W30+U30+S30+Q30+O30+M30+'input Licensee sales'!F21 -> 0
A31: Best Sox | B31: 100 | C31: Argentina | D31: ARS | E31: 2015 | AH31: =AF31+AD31+AB31+Z31+X31+V31+T31+R31+P31+N31+L31+'input Licensee sales'!#REF! -> #REF! | AI31: =AG31+AE31+AC31+AA31+Y31+W31+U31+S31+Q31+O31+M31+'input Licensee sales'!#REF! -> #REF!
A32: Best Sox | B32: 100 | C32: Argentina | D32: ARS | E32: 2015 | AH32: =AF32+AD32+AB32+Z32+X32+V32+T32+R32+P32+N32+L32+'input Licensee sales'!E22 -> 0 | AI32: =AG32+AE32+AC32+AA32+Y32+W32+U32+S32+Q32+O32+M32+'input Licensee sales'!F22 -> 0
A33: Best Sox | B33: 100 | C33: Argentina | D33: ARS | E33: 2015 | AH33: =AF33+AD33+AB33+Z33+X33+V33+T33+R33+P33+N33+L33+'input Licensee sales'!E23 -> 0 | AI33: =AG33+AE33+AC33+AA33+Y33+W33+U33+S33+Q33+O33+M33+'input Licensee sales'!F23 -> 0
A34: Best Sox | B34: 100 | C34: Argentina | D34: ARS | E34: 2015 | AH34: =AF34+AD34+AB34+Z34+X34+V34+T34+R34+P34+N34+L34+'input Licensee sales'!#REF! -> #REF! | AI34: =AG34+AE34+AC34+AA34+Y34+W34+U34+S34+Q34+O34+M34+'input Licensee sales'!#REF! -> #REF!
A35: Best Sox | B35: 100 | C35: Argentina | D35: ARS | E35: 2015 | AH35: =AF35+AD35+AB35+Z35+X35+V35+T35+R35+P35+N35+L35+'input Licensee sales'!E24 -> 0 | AI35: =AG35+AE35+AC35+AA35+Y35+W35+U35+S35+Q35+O35+M35+'input Licensee sales'!F24 -> 0
A36: Best Sox | B36: 100 | C36: Argentina | D36: ARS | E36: 2015 | AH36: =AF36+AD36+AB36+Z36+X36+V36+T36+R36+P36+N36+L36+J36 -> 0 | AI36: =AG36+AE36+AC36+AA36+Y36+W36+U36+S36+Q36+O36+M36+K36 -> 0
A37: Best Sox | B37: 100 | C37: Argentina | D37: ARS | E37: 2015 | AH37: =AF37+AD37+AB37+Z37+X37+V37+T37+R37+P37+N37+L37+J37 -> 0 | AI37: =AG37+AE37+AC37+AA37+Y37+W37+U37+S37+Q37+O37+M37+K37 -> 0
A38: Best Sox | B38: 100 | C38: Argentina | D38: ARS | E38: 2015 | AH38: =AF38+AD38+AB38+Z38+X38+V38+T38+R38+P38+N38+L38+J38 -> 0 | AI38: =AG38+AE38+AC38+AA38+Y38+W38+U38+S38+Q38+O38+M38+K38 -> 0
A39: Best Sox | B39: 100 | C39: Argentina | D39: ARS | E39: 2015 | AH39: =AF39+AD39+AB39+Z39+X39+V39+T39+R39+P39+N39+L39+J39 -> 0 | AI39: =AG39+AE39+AC39+AA39+Y39+W39+U39+S39+Q39+O39+M39+K39 -> 0
A40: Best Sox | B40: 100 | C40: Argentina | D40: ARS | E40: 2015 | AH40: =AF40+AD40+AB40+Z40+X40+V40+T40+R40+P40+N40+L40+J40 -> 0 | AI40: =AG40+AE40+AC40+AA40+Y40+W40+U40+S40+Q40+O40+M40+K40 -> 0
...

Sheet monthly
B2: Best Sox | D2: 01-2026 | E2: 02-2026 | F2: 03-2026 | G2: 1st quarter | H2: 04-2026 | I2: 05-2026 | J2: 06-2026 | K2: 2nd quarter | L2: 07-2026 | M2: 08-2026 | N2: 09-2026 | O2: 3th quarter | P2: 10-2026 | Q2: 11-2026 | R2: 12-2026 | S2: 4th quarter | T2: FY 2026
B4: dozens | D4: ='input Licensee sales'!E2 -> 14982.584 | E4: ='input Licensee sales'!G2 -> 22213.506 | F4: ='input Licensee sales'!I2 -> 19865.003 | G4: =SUM(D4:F4) -> 57061.093 | H4: ='input Licensee sales'!K2 -> 30709.589 | I4: ='input Licensee sales'!M2 -> 19682.843 | J4: ='input Licensee sales'!O2 -> 19497.333 | K4: =SUM(H4:J4) -> 69889.765 | L4: ='input Licensee sales'!Q2 -> 15145.169 | M4: ='input Licensee sales'!S2 -> 0 | N4: ='input Licensee sales'!U2 -> 0 | O4: =SUM(L4:N4) -> 15145.169 | P4: ='input Licensee sales'!W2 -> 0 | Q4: ='input Licensee sales'!Y2 -> 0 | R4: ='input Licensee sales'!AA2 -> 0 | S4: =SUM(P4:R4) -> 0 | T4: =G4+K4+O4+S4 -> 142096.03
B6: Sales | C6: ARS | D6: ='input Licensee sales'!F2 -> 3.0262652e+08 | E6: ='input Licensee sales'!H2 -> 4.7951415e+08 | F6: ='input Licensee sales'!J2 -> 4.3778361e+08 | G6: =SUM(D6:F6) -> 1.2199243e+09 | H6: ='input Licensee sales'!L2 -> 7.039591e+08 | I6: ='input Licensee sales'!N2 -> 4.6500257e+08 | J6: ='input Licensee sales'!P2 -> 4.8842752e+08 | K6: =SUM(H6:J6) -> 1.6573892e+09 | L6: ='input Licensee sales'!R2 -> 3.6582624e+08 | M6: ='input Licensee sales'!T2 -> 0 | N6: ='input Licensee sales'!V2 -> 0 | O6: =SUM(L6:N6) -> 3.6582624e+08 | P6: ='input Licensee sales'!X2 -> 0 | Q6: ='input Licensee sales'!Z2 -> 0 | R6: ='input Licensee sales'!AB2 -> 0 | S6: =SUM(P6:R6) -> 0 | T6: =G6+K6+O6+S6 -> 3.2431397e+09
C7: 0.13
B8: Royalty | C8: =C6 -> ARS | D8: =$C7*D6 -> 39341448 | E8: =$C7*E6 -> 62336840 | F8: =$C7*F6 -> 56911870 | G8: =SUM(D8:F8) -> 1.5859016e+08 | H8: =$C7*H6 -> 91514683 | I8: =$C7*I6 -> 60450334 | J8: =$C7*J6 -> 63495578 | K8: =SUM(H8:J8) -> 2.1546059e+08 | L8: =$C7*L6 -> 47557411 | M8: =$C7*M6 -> 0 | N8: =$C7*N6 -> 0 | O8: =SUM(L8:N8) -> 47557411 | P8: =$C7*P6 -> 0 | Q8: =$C7*Q6 -> 0 | R8: =$C7*R6 -> 0 | S8: =SUM(P8:R8) -> 0 | T8: =G8+K8+O8+S8 -> 4.2160816e+08
D13: FY 2026
D14: MINIMUM | E14: ACTUAL | F14: FORECAST | G14: EXPECTED total
B15: dozens | C15: #
B16: units | C16: #

Sheet minimum agreed
A1: licensee | B1: country | C1: currency | E1: minimum units
A2: Best Sox | B2: Argentina | C2: USD | D2: 2014 | E2: 2362500
A4: Best Sox | B4: Argentina | C4: # dozens | D4: 2021 | E4: 86540
A5: Best Sox | B5: Argentina | C5: # units | D5: 2021 | E5: 11106
A6: Best Sox | B6: Argentina | C6: # dozens | D6: 2022 | E6: 112502
A7: Best Sox | B7: Argentina | C7: # units | D7: 2022 | E7: 22212
A8: Best Sox | B8: Argentina | C8: # dozens | D8: 2023 | E8: 129378
A9: Best Sox | B9: Argentina | C9: # units | D9: 2023 | E9: 33318
